"D:\Python projects\OpenAI_Playground\.venv\Scripts\python.exe" "D:\Python projects\OpenAI_Playground\main.py" 
Traceback (most recent call last):
  File "D:\Python projects\OpenAI_Playground\main.py", line 4, in <module>
    response = client.chat.completions.create(
               ^^^^^^^^^^^^^^^^^^^^^^^^^^^^^^^
  File "D:\Python projects\OpenAI_Playground\.venv\Lib\site-packages\openai\_utils\_utils.py", line 303, in wrapper
    return func(*args, **kwargs)
           ^^^^^^^^^^^^^^^^^^^^^
  File "D:\Python projects\OpenAI_Playground\.venv\Lib\site-packages\openai\resources\chat\completions.py", line 645, in create
    return self._post(
           ^^^^^^^^^^^
  File "D:\Python projects\OpenAI_Playground\.venv\Lib\site-packages\openai\_base_client.py", line 1088, in post
    return cast(ResponseT, self.request(cast_to, opts, stream=stream, stream_cls=stream_cls))
                           ^^^^^^^^^^^^^^^^^^^^^^^^^^^^^^^^^^^^^^^^^^^^^^^^^^^^^^^^^^^^^^^^^
  File "D:\Python projects\OpenAI_Playground\.venv\Lib\site-packages\openai\_base_client.py", line 853, in request
    return self._request(
           ^^^^^^^^^^^^^^
  File "D:\Python projects\OpenAI_Playground\.venv\Lib\site-packages\openai\_base_client.py", line 916, in _request
    return self._retry_request(
           ^^^^^^^^^^^^^^^^^^^^
  File "D:\Python projects\OpenAI_Playground\.venv\Lib\site-packages\openai\_base_client.py", line 958, in _retry_request
    return self._request(
           ^^^^^^^^^^^^^^
  File "D:\Python projects\OpenAI_Playground\.venv\Lib\site-packages\openai\_base_client.py", line 916, in _request
    return self._retry_request(
           ^^^^^^^^^^^^^^^^^^^^
  File "D:\Python projects\OpenAI_Playground\.venv\Lib\site-packages\openai\_base_client.py", line 958, in _retry_request
    return self._request(
           ^^^^^^^^^^^^^^
  File "D:\Python projects\OpenAI_Playground\.venv\Lib\site-packages\openai\_base_client.py", line 930, in _request
    raise self._make_status_error_from_response(err.response) from None
openai.RateLimitError: Error code: 429 - {'error': {'message': 'You exceeded your current quota, please check your plan and billing details. For more information on this error, read the docs: https://platform.openai.com/docs/guides/error-codes/api-errors.', 'type': 'insufficient_quota', 'param': None, 'code': 'insufficient_quota'}}

Process finished with exit code 1
